Workbook

Sheet Dashboard
B2: FP&A REVENUE DASHBOARD
B3: Budget vs. Actual | Variance Analysis | UK FMCG Distribution Business — Rajnandan Basu
B5: Region Filter | C5: All | E5: Department Filter | F5: All | H5: RegionCrit | I5: =IF(C5="All","*",C5) -> * | J5: DeptCrit | K5: =IF(F5="All","*",F5) -> *
B6: Select a Region/Department above — all KPIs and charts update automatically.
B8: Total Budget | E8: Total Actual | H8: Variance (£) | K8: Variance (%)
B9: =SUMIFS(Data!$E:$E,Data!$C:$C,$I$5,Data!$D:$D,$K$5) -> 25751750 | E9: =SUMIFS(Data!$F:$F,Data!$C:$C,$I$5,Data!$D:$D,$K$5) -> 25684059 | H9: =E9-B9 -> -67691 | K9: =IFERROR(H9/B9,0) -> -0.0026285981
B13: MONTHLY TREND — BUDGET VS ACTUAL (filtered)
B14: Month | C14: Budget | D14: Actual
B15: Jan-25 | C15: =SUMIFS(Data!$E:$E,Data!$A:$A,"Jan-25",Data!$C:$C,$I$5,Data!$D:$D,$K$5) -> 1371439 | D15: =SUMIFS(Data!$F:$F,Data!$A:$A,"Jan-25",Data!$C:$C,$I$5,Data!$D:$D,$K$5) -> 1391327
B16: Feb-25 | C16: =SUMIFS(Data!$E:$E,Data!$A:$A,"Feb-25",Data!$C:$C,$I$5,Data!$D:$D,$K$5) -> 1430075 | D16: =SUMIFS(Data!$F:$F,Data!$A:$A,"Feb-25",Data!$C:$C,$I$5,Data!$D:$D,$K$5) -> 1448450
B17: Mar-25 | C17: =SUMIFS(Data!$E:$E,Data!$A:$A,"Mar-25",Data!$C:$C,$I$5,Data!$D:$D,$K$5) -> 1463546 | D17: =SUMIFS(Data!$F:$F,Data!$A:$A,"Mar-25",Data!$C:$C,$I$5,Data!$D:$D,$K$5) -> 1418632
B18: Apr-25 | C18: =SUMIFS(Data!$E:$E,Data!$A:$A,"Apr-25",Data!$C:$C,$I$5,Data!$D:$D,$K$5) -> 1464969 | D18: =SUMIFS(Data!$F:$F,Data!$A:$A,"Apr-25",Data!$C:$C,$I$5,Data!$D:$D,$K$5) -> 1462822
B19: May-25 | C19: =SUMIFS(Data!$E:$E,Data!$A:$A,"May-25",Data!$C:$C,$I$5,Data!$D:$D,$K$5) -> 1436016 | D19: =SUMIFS(Data!$F:$F,Data!$A:$A,"May-25",Data!$C:$C,$I$5,Data!$D:$D,$K$5) -> 1417755
B20: Jun-25 | C20: =SUMIFS(Data!$E:$E,Data!$A:$A,"Jun-25",Data!$C:$C,$I$5,Data!$D:$D,$K$5) -> 1386590 | D20: =SUMIFS(Data!$F:$F,Data!$A:$A,"Jun-25",Data!$C:$C,$I$5,Data!$D:$D,$K$5) -> 1424326
B21: Jul-25 | C21: =SUMIFS(Data!$E:$E,Data!$A:$A,"Jul-25",Data!$C:$C,$I$5,Data!$D:$D,$K$5) -> 1332263 | D21: =SUMIFS(Data!$F:$F,Data!$A:$A,"Jul-25",Data!$C:$C,$I$5,Data!$D:$D,$K$5) -> 1381226
B22: Aug-25 | C22: =SUMIFS(Data!$E:$E,Data!$A:$A,"Aug-25",Data!$C:$C,$I$5,Data!$D:$D,$K$5) -> 1290128 | D22: =SUMIFS(Data!$F:$F,Data!$A:$A,"Aug-25",Data!$C:$C,$I$5,Data!$D:$D,$K$5) -> 1303677
B23: Sep-25 | C23: =SUMIFS(Data!$E:$E,Data!$A:$A,"Sep-25",Data!$C:$C,$I$5,Data!$D:$D,$K$5) -> 1274233 | D23: =SUMIFS(Data!$F:$F,Data!$A:$A,"Sep-25",Data!$C:$C,$I$5,Data!$D:$D,$K$5) -> 1250489
B24: Oct-25 | C24: =SUMIFS(Data!$E:$E,Data!$A:$A,"Oct-25",Data!$C:$C,$I$5,Data!$D:$D,$K$5) -> 1291719 | D24: =SUMIFS(Data!$F:$F,Data!$A:$A,"Oct-25",Data!$C:$C,$I$5,Data!$D:$D,$K$5) -> 1251186
B25: Nov-25 | C25: =SUMIFS(Data!$E:$E,Data!$A:$A,"Nov-25",Data!$C:$C,$I$5,Data!$D:$D,$K$5) -> 1340814 | D25: =SUMIFS(Data!$F:$F,Data!$A:$A,"Nov-25",Data!$C:$C,$I$5,Data!$D:$D,$K$5) -> 1330323
B26: Dec-25 | C26: =SUMIFS(Data!$E:$E,Data!$A:$A,"Dec-25",Data!$C:$C,$I$5,Data!$D:$D,$K$5) -> 1411191 | D26: =SUMIFS(Data!$F:$F,Data!$A:$A,"Dec-25",Data!$C:$C,$I$5,Data!$D:$D,$K$5) -> 1417970
B27: Jan-26 | C27: =SUMIFS(Data!$E:$E,Data!$A:$A,"Jan-26",Data!$C:$C,$I$5,Data!$D:$D,$K$5) -> 1486641 | D27: =SUMIFS(Data!$F:$F,Data!$A:$A,"Jan-26",Data!$C:$C,$I$5,Data!$D:$D,$K$5) -> 1459694
B28: Feb-26 | C28: =SUMIFS(Data!$E:$E,Data!$A:$A,"Feb-26",Data!$C:$C,$I$5,Data!$D:$D,$K$5) -> 1549367 | D28: =SUMIFS(Data!$F:$F,Data!$A:$A,"Feb-26",Data!$C:$C,$I$5,Data!$D:$D,$K$5) -> 1537887
B29: Mar-26 | C29: =SUMIFS(Data!$E:$E,Data!$A:$A,"Mar-26",Data!$C:$C,$I$5,Data!$D:$D,$K$5) -> 1584786 | D29: =SUMIFS(Data!$F:$F,Data!$A:$A,"Mar-26",Data!$C:$C,$I$5,Data!$D:$D,$K$5) -> 1594462
B30: Apr-26 | C30: =SUMIFS(Data!$E:$E,Data!$A:$A,"Apr-26",Data!$C:$C,$I$5,Data!$D:$D,$K$5) -> 1585492 | D30: =SUMIFS(Data!$F:$F,Data!$A:$A,"Apr-26",Data!$C:$C,$I$5,Data!$D:$D,$K$5) -> 1563262
B31: May-26 | C31: =SUMIFS(Data!$E:$E,Data!$A:$A,"May-26",Data!$C:$C,$I$5,Data!$D:$D,$K$5) -> 1553355 | D31: =SUMIFS(Data!$F:$F,Data!$A:$A,"May-26",Data!$C:$C,$I$5,Data!$D:$D,$K$5) -> 1568952
B32: Jun-26 | C32: =SUMIFS(Data!$E:$E,Data!$A:$A,"Jun-26",Data!$C:$C,$I$5,Data!$D:$D,$K$5) -> 1499126 | D32: =SUMIFS(Data!$F:$F,Data!$A:$A,"Jun-26",Data!$C:$C,$I$5,Data!$D:$D,$K$5) -> 1461619
B35: REGIONAL PERFORMANCE (full year, all departments)
B36: Region | C36: Budget | D36: Actual | E36: Variance %
B37: London | C37: =SUMIFS(Data!$E:$E,Data!$C:$C,"London") -> 9328933 | D37: =SUMIFS(Data!$F:$F,Data!$C:$C,"London") -> 9310655 | E37: =(D37-C37)/C37 -> -0.0019592809
B38: Manchester | C38: =SUMIFS(Data!$E:$E,Data!$C:$C,"Manchester") -> 6607997 | D38: =SUMIFS(Data!$F:$F,Data!$C:$C,"Manchester") -> 6580934 | E38: =(D38-C38)/C38 -> -0.0040954922
B39: Birmingham | C39: =SUMIFS(Data!$E:$E,Data!$C:$C,"Birmingham") -> 5733411 | D39: =SUMIFS(Data!$F:$F,Data!$C:$C,"Birmingham") -> 5691465 | E39: =(D39-C39)/C39 -> -0.0073160637
B40: Leeds | C40: =SUMIFS(Data!$E:$E,Data!$C:$C,"Leeds") -> 4081409 | D40: =SUMIFS(Data!$F:$F,Data!$C:$C,"Leeds") -> 4101005 | E40: =(D40-C40)/C40 -> 0.0048012831
B43: REVENUE MIX BY DEPARTMENT (Actual, full year)
B44: Department | C44: Actual Revenue
B45: Retail Sales | C45: =SUMIFS(Data!$F:$F,Data!$D:$D,"Retail Sales") -> 10852672
B46: Wholesale | C46: =SUMIFS(Data!$F:$F,Data!$D:$D,"Wholesale") -> 7154748
B47: Online Sales | C47: =SUMIFS(Data!$F:$F,Data!$D:$D,"Online Sales") -> 4590236
B48: Foodservice | C48: =SUMIFS(Data!$F:$F,Data!$D:$D,"Foodservice") -> 3086403
B51: INSIGHTS
B52: Best performing region (Actual vs Budget): | E52: =INDEX(B37:B40,MATCH(MAX(E37:E40),E37:E40,0)) -> Leeds
...

Sheet Data
A1: Month | B1: MonthIndex | C1: Region | D1: Department | E1: Budget | F1: Actual | G1: Variance | H1: Variance %
A2: Jan-25 | B2: 1 | C2: London | D2: Retail Sales | E2: 208666 | F2: 236886 | G2: 28220 | H2: 13.5
A3: Jan-25 | B3: 1 | C3: London | D3: Wholesale | E3: 139110 | F3: 133925 | G3: -5185 | H3: -3.7
A4: Jan-25 | B4: 1 | C4: London | D4: Online Sales | E4: 89428 | F4: 89663 | G4: 235 | H4: 0.3
A5: Jan-25 | B5: 1 | C5: London | D5: Foodservice | E5: 59619 | F5: 61562 | G5: 1943 | H5: 3.3
A6: Jan-25 | B6: 1 | C6: Manchester | D6: Retail Sales | E6: 147805 | F6: 138476 | G6: -9329 | H6: -6.3
A7: Jan-25 | B7: 1 | C7: Manchester | D7: Wholesale | E7: 98537 | F7: 98553 | G7: 16 | H7: 0
A8: Jan-25 | B8: 1 | C8: Manchester | D8: Online Sales | E8: 63345 | F8: 63340 | G8: -5 | H8: 0
A9: Jan-25 | B9: 1 | C9: Manchester | D9: Foodservice | E9: 42230 | F9: 36302 | G9: -5928 | H9: -14
A10: Jan-25 | B10: 1 | C10: Birmingham | D10: Retail Sales | E10: 128242 | F10: 138683 | G10: 10441 | H10: 8.1
A11: Jan-25 | B11: 1 | C11: Birmingham | D11: Wholesale | E11: 85495 | F11: 89602 | G11: 4107 | H11: 4.8
A12: Jan-25 | B12: 1 | C12: Birmingham | D12: Online Sales | E12: 54961 | F12: 52211 | G12: -2750 | H12: -5
A13: Jan-25 | B13: 1 | C13: Birmingham | D13: Foodservice | E13: 36641 | F13: 36138 | G13: -503 | H13: -1.4
... A289: Jun-26 | B289: 18 | C289: Leeds | D289: Foodservice | E289: 28512 | F289: 25999 | G289: -2513 | H289: -8.8
