Workbook

Sheet Dashboard
B2: BUDGET vs ACTUAL FP&A DASHBOARD
B3: Monthly Variance Analysis | Revenue & Expense Tracking | Forecast Accuracy — Rajnandan Basu
B5: Month Filter | C5: All | H5: MonthCrit | I5: =IF(C5="All","*",C5) -> *
B6: Select a month above, or "All" for full-period totals — KPIs update automatically.
B8: Revenue: Budget | E8: Revenue: Actual | H8: Revenue Variance % | K8: Forecast Accuracy % (Full Period)
B9: =SUMIFS(Data!$E:$E,Data!$A:$A,$I$5,Data!$C:$C,"Revenue") -> 29478828 | E9: =SUMIFS(Data!$F:$F,Data!$A:$A,$I$5,Data!$C:$C,"Revenue") -> 29485309 | H9: =IFERROR((E9-B9)/B9,0) -> 0.0002198527 | K9: =1-SUMPRODUCT(ABS(Data!$G$2:$G$217-Data!$F$2:$F$217)*(Data!$C$2:$C$217="Revenue"))/SUMIFS(Data!$F:$F,Data!$C:$C,"Revenue") -> 0.96051356
B11: Expense: Budget | E11: Expense: Actual | H11: Expense Variance % | K11: Net Variance (£)
B12: =SUMIFS(Data!$E:$E,Data!$A:$A,$I$5,Data!$C:$C,"Expense") -> 28325307 | E12: =SUMIFS(Data!$F:$F,Data!$A:$A,$I$5,Data!$C:$C,"Expense") -> 28302005 | H12: =IFERROR((E12-B12)/B12,0) -> -0.00082265657 | K12: =(E9-B9)-(E12-B12) -> 29783
B15: MONTHLY REVENUE: BUDGET vs ACTUAL
B16: Month | C16: Budget | D16: Actual
B17: Jan-25 | C17: =SUMIFS(Data!$E:$E,Data!$A:$A,"Jan-25",Data!$C:$C,"Revenue") -> 1177188 | D17: =SUMIFS(Data!$F:$F,Data!$A:$A,"Jan-25",Data!$C:$C,"Revenue") -> 1208440
B18: Feb-25 | C18: =SUMIFS(Data!$E:$E,Data!$A:$A,"Feb-25",Data!$C:$C,"Revenue") -> 1224796 | D18: =SUMIFS(Data!$F:$F,Data!$A:$A,"Feb-25",Data!$C:$C,"Revenue") -> 1131243
B19: Mar-25 | C19: =SUMIFS(Data!$E:$E,Data!$A:$A,"Mar-25",Data!$C:$C,"Revenue") -> 1254585 | D19: =SUMIFS(Data!$F:$F,Data!$A:$A,"Mar-25",Data!$C:$C,"Revenue") -> 1259931
B20: Apr-25 | C20: =SUMIFS(Data!$E:$E,Data!$A:$A,"Apr-25",Data!$C:$C,"Revenue") -> 1260173 | D20: =SUMIFS(Data!$F:$F,Data!$A:$A,"Apr-25",Data!$C:$C,"Revenue") -> 1213401
B21: May-25 | C21: =SUMIFS(Data!$E:$E,Data!$A:$A,"May-25",Data!$C:$C,"Revenue") -> 1241622 | D21: =SUMIFS(Data!$F:$F,Data!$A:$A,"May-25",Data!$C:$C,"Revenue") -> 1239122
B22: Jun-25 | C22: =SUMIFS(Data!$E:$E,Data!$A:$A,"Jun-25",Data!$C:$C,"Revenue") -> 1205512 | D22: =SUMIFS(Data!$F:$F,Data!$A:$A,"Jun-25",Data!$C:$C,"Revenue") -> 1188400
B23: Jul-25 | C23: =SUMIFS(Data!$E:$E,Data!$A:$A,"Jul-25",Data!$C:$C,"Revenue") -> 1163233 | D23: =SUMIFS(Data!$F:$F,Data!$A:$A,"Jul-25",Data!$C:$C,"Revenue") -> 1094606
B24: Aug-25 | C24: =SUMIFS(Data!$E:$E,Data!$A:$A,"Aug-25",Data!$C:$C,"Revenue") -> 1127975 | D24: =SUMIFS(Data!$F:$F,Data!$A:$A,"Aug-25",Data!$C:$C,"Revenue") -> 1037319
B25: Sep-25 | C25: =SUMIFS(Data!$E:$E,Data!$A:$A,"Sep-25",Data!$C:$C,"Revenue") -> 1111185 | D25: =SUMIFS(Data!$F:$F,Data!$A:$A,"Sep-25",Data!$C:$C,"Revenue") -> 1151756
B26: Oct-25 | C26: =SUMIFS(Data!$E:$E,Data!$A:$A,"Oct-25",Data!$C:$C,"Revenue") -> 1119463 | D26: =SUMIFS(Data!$F:$F,Data!$A:$A,"Oct-25",Data!$C:$C,"Revenue") -> 1084481
B27: Nov-25 | C27: =SUMIFS(Data!$E:$E,Data!$A:$A,"Nov-25",Data!$C:$C,"Revenue") -> 1152727 | D27: =SUMIFS(Data!$F:$F,Data!$A:$A,"Nov-25",Data!$C:$C,"Revenue") -> 1111088
B28: Dec-25 | C28: =SUMIFS(Data!$E:$E,Data!$A:$A,"Dec-25",Data!$C:$C,"Revenue") -> 1204154 | D28: =SUMIFS(Data!$F:$F,Data!$A:$A,"Dec-25",Data!$C:$C,"Revenue") -> 1296100
B29: Jan-26 | C29: =SUMIFS(Data!$E:$E,Data!$A:$A,"Jan-26",Data!$C:$C,"Revenue") -> 1261945 | D29: =SUMIFS(Data!$F:$F,Data!$A:$A,"Jan-26",Data!$C:$C,"Revenue") -> 1291383
B30: Feb-26 | C30: =SUMIFS(Data!$E:$E,Data!$A:$A,"Feb-26",Data!$C:$C,"Revenue") -> 1312455 | D30: =SUMIFS(Data!$F:$F,Data!$A:$A,"Feb-26",Data!$C:$C,"Revenue") -> 1379903
B31: Mar-26 | C31: =SUMIFS(Data!$E:$E,Data!$A:$A,"Mar-26",Data!$C:$C,"Revenue") -> 1343846 | D31: =SUMIFS(Data!$F:$F,Data!$A:$A,"Mar-26",Data!$C:$C,"Revenue") -> 1326208
B32: Apr-26 | C32: =SUMIFS(Data!$E:$E,Data!$A:$A,"Apr-26",Data!$C:$C,"Revenue") -> 1349302 | D32: =SUMIFS(Data!$F:$F,Data!$A:$A,"Apr-26",Data!$C:$C,"Revenue") -> 1437707
B33: May-26 | C33: =SUMIFS(Data!$E:$E,Data!$A:$A,"May-26",Data!$C:$C,"Revenue") -> 1328924 | D33: =SUMIFS(Data!$F:$F,Data!$A:$A,"May-26",Data!$C:$C,"Revenue") -> 1292078
B34: Jun-26 | C34: =SUMIFS(Data!$E:$E,Data!$A:$A,"Jun-26",Data!$C:$C,"Revenue") -> 1289781 | D34: =SUMIFS(Data!$F:$F,Data!$A:$A,"Jun-26",Data!$C:$C,"Revenue") -> 1310101
B35: Jul-26 | C35: =SUMIFS(Data!$E:$E,Data!$A:$A,"Jul-26",Data!$C:$C,"Revenue") -> 1244076 | D35: =SUMIFS(Data!$F:$F,Data!$A:$A,"Jul-26",Data!$C:$C,"Revenue") -> 1279890
B36: Aug-26 | C36: =SUMIFS(Data!$E:$E,Data!$A:$A,"Aug-26",Data!$C:$C,"Revenue") -> 1205916 | D36: =SUMIFS(Data!$F:$F,Data!$A:$A,"Aug-26",Data!$C:$C,"Revenue") -> 1250876
B37: Sep-26 | C37: =SUMIFS(Data!$E:$E,Data!$A:$A,"Sep-26",Data!$C:$C,"Revenue") -> 1187525 | D37: =SUMIFS(Data!$F:$F,Data!$A:$A,"Sep-26",Data!$C:$C,"Revenue") -> 1096363
B38: Oct-26 | C38: =SUMIFS(Data!$E:$E,Data!$A:$A,"Oct-26",Data!$C:$C,"Revenue") -> 1195935 | D38: =SUMIFS(Data!$F:$F,Data!$A:$A,"Oct-26",Data!$C:$C,"Revenue") -> 1208719
B39: Nov-26 | C39: =SUMIFS(Data!$E:$E,Data!$A:$A,"Nov-26",Data!$C:$C,"Revenue") -> 1231025 | D39: =SUMIFS(Data!$F:$F,Data!$A:$A,"Nov-26",Data!$C:$C,"Revenue") -> 1311042
B40: Dec-26 | C40: =SUMIFS(Data!$E:$E,Data!$A:$A,"Dec-26",Data!$C:$C,"Revenue") -> 1285485 | D40: =SUMIFS(Data!$F:$F,Data!$A:$A,"Dec-26",Data!$C:$C,"Revenue") -> 1285152
B43: MONTHLY EXPENSE: BUDGET vs ACTUAL
B44: Month | C44: Budget | D44: Actual
B45: Jan-25 | C45: =SUMIFS(Data!$E:$E,Data!$A:$A,"Jan-25",Data!$C:$C,"Expense") -> 1131124 | D45: =SUMIFS(Data!$F:$F,Data!$A:$A,"Jan-25",Data!$C:$C,"Expense") -> 1178140
B46: Feb-25 | C46: =SUMIFS(Data!$E:$E,Data!$A:$A,"Feb-25",Data!$C:$C,"Expense") -> 1176870 | D46: =SUMIFS(Data!$F:$F,Data!$A:$A,"Feb-25",Data!$C:$C,"Expense") -> 1196035
B47: Mar-25 | C47: =SUMIFS(Data!$E:$E,Data!$A:$A,"Mar-25",Data!$C:$C,"Expense") -> 1205494 | D47: =SUMIFS(Data!$F:$F,Data!$A:$A,"Mar-25",Data!$C:$C,"Expense") -> 1242149
B48: Apr-25 | C48: =SUMIFS(Data!$E:$E,Data!$A:$A,"Apr-25",Data!$C:$C,"Expense") -> 1210862 | D48: =SUMIFS(Data!$F:$F,Data!$A:$A,"Apr-25",Data!$C:$C,"Expense") -> 1192454
...

Sheet Data
A1: Month | B1: MonthIndex | C1: Type | D1: Category | E1: Budget | F1: Actual | G1: Forecast
A2: Jan-25 | B2: 1 | C2: Revenue | D2: Retail Sales | E2: 491348 | F2: 489561 | G2: 487111
A3: Jan-25 | B3: 1 | C3: Revenue | D3: Wholesale | E3: 327565 | F3: 351453 | G3: 331577
A4: Jan-25 | B4: 1 | C4: Revenue | D4: Online Sales | E4: 214965 | F4: 226181 | G4: 208766
A5: Jan-25 | B5: 1 | C5: Revenue | D5: Foodservice | E5: 143310 | F5: 141245 | G5: 139754
A6: Jan-25 | B6: 1 | C6: Expense | D6: Cost of Goods Sold | E6: 665367 | F6: 710405 | G6: 710046
A7: Jan-25 | B7: 1 | C7: Expense | D7: Payroll | E7: 245674 | F7: 236635 | G7: 249638
A8: Jan-25 | B8: 1 | C8: Expense | D8: Marketing | E8: 66537 | F8: 72968 | G8: 70956
A9: Jan-25 | B9: 1 | C9: Expense | D9: Logistics & Distribution | E9: 97246 | F9: 101283 | G9: 99468
A10: Jan-25 | B10: 1 | C10: Expense | D10: Admin & Overheads | E10: 56300 | F10: 56849 | G10: 57434
A11: Feb-25 | B11: 2 | C11: Revenue | D11: Retail Sales | E11: 511219 | F11: 465576 | G11: 466917
A12: Feb-25 | B12: 2 | C12: Revenue | D12: Wholesale | E12: 340813 | F12: 315480 | G12: 301434
A13: Feb-25 | B13: 2 | C13: Revenue | D13: Online Sales | E13: 223658 | F13: 216492 | G13: 197162
... A217: Dec-26 | B217: 24 | C217: Expense | D217: Admin & Overheads | E217: 61480 | F217: 60838 | G217: 62486
